2025-03-04 09:45:36,870 INFO    MainThread:13039 [wandb_init.py:setup_run_log_directory():647] Logging user logs to /home/w2sg-arnav/cotton-disease/notebooks/wandb/offline-run-20250304_094536-lrlu4us5/logs/debug.log
2025-03-04 09:45:36,870 INFO    MainThread:13039 [wandb_init.py:setup_run_log_directory():648] Logging internal logs to /home/w2sg-arnav/cotton-disease/notebooks/wandb/offline-run-20250304_094536-lrlu4us5/logs/debug-internal.log
2025-03-04 09:45:36,870 INFO    MainThread:13039 [wandb_init.py:init():761] calling init triggers
2025-03-04 09:45:36,870 INFO    MainThread:13039 [wandb_init.py:init():766] wandb.init called with sweep_config: {}
config: {'_wandb': {}}
2025-03-04 09:45:36,870 INFO    MainThread:13039 [wandb_init.py:init():784] starting backend
2025-03-04 09:45:36,870 INFO    MainThread:13039 [wandb_init.py:init():788] sending inform_init request
2025-03-04 09:45:36,871 INFO    MainThread:13039 [backend.py:_multiprocessing_setup():97] multiprocessing start_methods=fork,spawn,forkserver, using: spawn
2025-03-04 09:45:36,871 INFO    MainThread:13039 [wandb_init.py:init():803] backend started and connected
2025-03-04 09:45:36,874 INFO    MainThread:13039 [wandb_run.py:_label_probe_notebook():1204] probe notebook
2025-03-04 09:45:36,875 WARNING MsgRouterThr:13039 [router.py:message_loop():77] message_loop has been closed
Traceback (most recent call last):
  File "/home/w2sg-arnav/anaconda3/envs/cotton_env/lib/python3.9/site-packages/wandb/sdk/interface/router_sock.py", line 28, in _read_message
    resp = self._sock_client.read_server_response(timeout=1)
  File "/home/w2sg-arnav/anaconda3/envs/cotton_env/lib/python3.9/site-packages/wandb/sdk/lib/sock_client.py", line 285, in read_server_response
    data = self._read_packet_bytes(timeout=timeout)
  File "/home/w2sg-arnav/anaconda3/envs/cotton_env/lib/python3.9/site-packages/wandb/sdk/lib/sock_client.py", line 270, in _read_packet_bytes
    raise SockClientClosedError
wandb.sdk.lib.sock_client.SockClientClosedError

The above exception was the direct cause of the following exception:

Traceback (most recent call last):
  File "/home/w2sg-arnav/anaconda3/envs/cotton_env/lib/python3.9/site-packages/wandb/sdk/interface/router.py", line 70, in message_loop
    msg = self._read_message()
  File "/home/w2sg-arnav/anaconda3/envs/cotton_env/lib/python3.9/site-packages/wandb/sdk/interface/router_sock.py", line 30, in _read_message
    raise MessageRouterClosedError from e
wandb.sdk.interface.router.MessageRouterClosedError
2025-03-04 09:45:36,875 INFO    MsgRouterThr:13039 [mailbox.py:close():115] Closing mailbox, abandoning 0 handles.
2025-03-04 09:45:36,876 INFO    MainThread:13039 [wandb_init.py:init():896] updated telemetry
2025-03-04 09:45:36,876 ERROR   MainThread:13039 [wandb_init.py:init():1481] error in wandb.init()
Traceback (most recent call last):
  File "/home/w2sg-arnav/anaconda3/envs/cotton_env/lib/python3.9/site-packages/wandb/sdk/wandb_init.py", line 1471, in init
    return wi.init(run_settings, run_config)
  File "/home/w2sg-arnav/anaconda3/envs/cotton_env/lib/python3.9/site-packages/wandb/sdk/wandb_init.py", line 903, in init
    backend.interface.publish_header()
  File "/home/w2sg-arnav/anaconda3/envs/cotton_env/lib/python3.9/site-packages/wandb/sdk/interface/interface.py", line 99, in publish_header
    self._publish_header(header)
  File "/home/w2sg-arnav/anaconda3/envs/cotton_env/lib/python3.9/site-packages/wandb/sdk/interface/interface_shared.py", line 283, in _publish_header
    self._publish(rec)
  File "/home/w2sg-arnav/anaconda3/envs/cotton_env/lib/python3.9/site-packages/wandb/sdk/interface/interface_sock.py", line 46, in _publish
    self._sock_client.send_record_publish(record)
  File "/home/w2sg-arnav/anaconda3/envs/cotton_env/lib/python3.9/site-packages/wandb/sdk/lib/sock_client.py", line 224, in send_record_publish
    self.send_server_request(server_req)
  File "/home/w2sg-arnav/anaconda3/envs/cotton_env/lib/python3.9/site-packages/wandb/sdk/lib/sock_client.py", line 154, in send_server_request
    self._send_message(msg)
  File "/home/w2sg-arnav/anaconda3/envs/cotton_env/lib/python3.9/site-packages/wandb/sdk/lib/sock_client.py", line 151, in _send_message
    self._sendall_with_error_handle(header + data)
  File "/home/w2sg-arnav/anaconda3/envs/cotton_env/lib/python3.9/site-packages/wandb/sdk/lib/sock_client.py", line 130, in _sendall_with_error_handle
    sent = self._sock.send(data)
BrokenPipeError: [Errno 32] Broken pipe
